<?xml version="1.0"?>
<sdf version="1.8">
  <model name="tricycle_robot">
    
    <!-- Base Link -->
    <link name="base_link">
      <pose>0 0 0.1 0 0 0</pose>
      <inertial>
        <mass>2.0</mass>
        <inertia>
          <ixx>0.0229</ixx>
          <iyy>0.0458</iyy>
          <izz>0.0583</izz>
        </inertia>
      </inertial>
      
      <visual name="visual">
        <geometry>
          <box>
            <size>0.5 0.3 0.15</size>
          </box>
        </geometry>
        <material>
          <ambient>0 0 1 1</ambient>
          <diffuse>0 0 1 1</diffuse>
        </material>
      </visual>
      
      <collision name="collision">
        <geometry>
          <box>
            <size>0.5 0.3 0.15</size>
          </box>
        </geometry>
      </collision>
    </link>

    <!-- Rear Left Wheel -->
    <link name="rear_left_wheel">
      <pose>-0.15 0.18 0.025 -1.57 0 0</pose>
      <inertial>
        <mass>0.5</mass>
        <inertia>
          <ixx>0.001</ixx>
          <iyy>0.001</iyy>
          <izz>0.0016</izz>
        </inertia>
      </inertial>
      
      <visual name="visual">
        <geometry>
          <cylinder>
            <radius>0.08</radius>
            <length>0.05</length>
          </cylinder>
        </geometry>
        <material>
          <ambient>0 0 0 1</ambient>
          <diffuse>0 0 0 1</diffuse>
        </material>
      </visual>
      
      <collision name="collision">
        <geometry>
          <cylinder>
            <radius>0.08</radius>
            <length>0.05</length>
          </cylinder>
        </geometry>
        <surface>
          <friction>
            <ode>
              <mu>1.0</mu>
              <mu2>1.0</mu2>
            </ode>
          </friction>
        </surface>
      </collision>
    </link>

    <joint name="rear_left_wheel_joint" type="revolute">
      <parent>base_link</parent>
      <child>rear_left_wheel</child>
      <axis>
        <xyz>0 0 1</xyz>
        <limit>
          <lower>-1e16</lower>
          <upper>1e16</upper>
        </limit>
      </axis>
    </joint>

    <!-- Rear Right Wheel -->
    <link name="rear_right_wheel">
      <pose>-0.15 -0.18 0.025 1.57 0 0</pose>
      <inertial>
        <mass>0.5</mass>
        <inertia>
          <ixx>0.001</ixx>
          <iyy>0.001</iyy>
          <izz>0.0016</izz>
        </inertia>
      </inertial>
      
      <visual name="visual">
        <geometry>
          <cylinder>
            <radius>0.08</radius>
            <length>0.05</length>
          </cylinder>
        </geometry>
        <material>
          <ambient>0 0 0 1</ambient>
          <diffuse>0 0 0 1</diffuse>
        </material>
      </visual>
      
      <collision name="collision">
        <geometry>
          <cylinder>
            <radius>0.08</radius>
            <length>0.05</length>
          </cylinder>
        </geometry>
        <surface>
          <friction>
            <ode>
              <mu>1.0</mu>
              <mu2>1.0</mu2>
            </ode>
          </friction>
        </surface>
      </collision>
    </link>

    <joint name="rear_right_wheel_joint" type="revolute">
      <parent>base_link</parent>
      <child>rear_right_wheel</child>
      <axis>
        <xyz>0 0 -1</xyz>
        <limit>
          <lower>-1e16</lower>
          <upper>1e16</upper>
        </limit>
      </axis>
    </joint>

    <!-- Front Wheel -->
    <link name="front_wheel">
      <pose>0.15 0 0.025 -1.57 0 0</pose>
      <inertial>
        <mass>0.5</mass>
        <inertia>
          <ixx>0.001</ixx>
          <iyy>0.001</iyy>
          <izz>0.0016</izz>
        </inertia>
      </inertial>
      
      <visual name="visual">
        <geometry>
          <cylinder>
            <radius>0.08</radius>
            <length>0.05</length>
          </cylinder>
        </geometry>
        <material>
          <ambient>0 0 0 1</ambient>
          <diffuse>0 0 0 1</diffuse>
        </material>
      </visual>
      
      <collision name="collision">
        <geometry>
          <cylinder>
            <radius>0.08</radius>
            <length>0.05</length>
          </cylinder>
        </geometry>
        <surface>
          <friction>
            <ode>
              <mu>0.5</mu>
              <mu2>0.5</mu2>
            </ode>
          </friction>
        </surface>
      </collision>
    </link>

    <joint name="front_wheel_joint" type="revolute">
      <parent>base_link</parent>
      <child>front_wheel</child>
      <axis>
        <xyz>0 0 1</xyz>
        <limit>
          <lower>-1e16</lower>
          <upper>1e16</upper>
        </limit>
      </axis>
    </joint>

    <!-- Camera Link -->
    <link name="camera_link">
      <pose>0.25 0 0.2 0 0 0</pose>
      <inertial>
        <mass>0.1</mass>
        <inertia>
          <ixx>0.0001</ixx>
          <iyy>0.0001</iyy>
          <izz>0.0001</izz>
        </inertia>
      </inertial>
      
      <visual name="visual">
        <geometry>
          <box>
            <size>0.05 0.08 0.05</size>
          </box>
        </geometry>
        <material>
          <ambient>1 0 0 1</ambient>
          <diffuse>1 0 0 1</diffuse>
        </material>
      </visual>
      
      <collision name="collision">
        <geometry>
          <box>
            <size>0.05 0.08 0.05</size>
          </box>
        </geometry>
      </collision>
      
      <sensor name="camera" type="camera">
        <always_on>1</always_on>
        <update_rate>30</update_rate>
        <visualize>true</visualize>
        <topic>/camera/image</topic>
        
        <camera>
          <horizontal_fov>1.047</horizontal_fov>
          <image>
            <width>640</width>
            <height>480</height>
            <format>R8G8B8</format>
          </image>
          <clip>
            <near>0.05</near>
            <far>0.5</far>
          </clip>
        </camera>
      </sensor>
    </link>

    <joint name="camera_joint" type="fixed">
      <parent>base_link</parent>
      <child>camera_link</child>
    </joint>

    <!-- Differential Drive Plugin for ROS2 Humble -->
    <plugin filename="libgz-sim-diff-drive-system.so" name="gz::sim::systems::DiffDrive">
      <left_joint>rear_left_wheel_joint</left_joint>
      <right_joint>rear_right_wheel_joint</right_joint>
      <wheel_separation>0.36</wheel_separation>
      <wheel_radius>0.08</wheel_radius>
      <odom_publish_frequency>50</odom_publish_frequency>
      <topic>cmd_vel</topic>
      <odom_topic>odometry</odom_topic>
      <frame_id>odom</frame_id>
      <child_frame_id>base_link</child_frame_id>
    </plugin>

    <!-- Sensors System Plugin (Required for camera to work) -->
    <plugin filename="libgz-sim-sensors-system.so" name="gz::sim::systems::Sensors">
      <render_engine>ogre2</render_engine>
    </plugin>

  </model>
</sdf>