<robot name="tricycle_robot">

  <!-- Base Link -->
  <link name="base_link">
    <visual>
      <geometry>
        <box size="0.5 0.3 0.15"/>
      </geometry>
      <origin xyz="0 0 0" rpy="0 0 0"/>
      <material name="blue">
        <color rgba="0 0 1 1"/>
      </material>
    </visual>

    <collision>
      <geometry>
        <box size="0.5 0.3 0.15"/>
      </geometry>
      <origin xyz="0 0 0" rpy="0 0 0"/>
    </collision>

    <inertial>
      <mass value="2.0"/>
      <inertia ixx="0.0229" ixy="0" ixz="0" iyy="0.0458" iyz="0" izz="0.0583"/>
    </inertial>
  </link>

  <!-- Rear Left Wheel (Drive Wheel) -->
  <link name="rear_left_wheel">
    <visual>
      <geometry>
        <cylinder radius="0.08" length="0.05"/>
      </geometry>
      <origin xyz="0 0 0" rpy="0 0 0"/>
      <material name="black">
        <color rgba="0 0 0 1"/>
      </material>
    </visual>

    <collision>
      <geometry>
        <cylinder radius="0.08" length="0.05"/>
      </geometry>
      <origin xyz="0 0 0" rpy="0 0 0"/>
    </collision>

    <inertial>
      <mass value="0.5"/>
      <inertia ixx="0.001" ixy="0" ixz="0" iyy="0.001" iyz="0" izz="0.0016"/>
    </inertial>
  </link>

  <joint name="base_to_rear_left_wheel" type="continuous">
    <parent link="base_link"/>
    <child link="rear_left_wheel"/>
    <origin xyz="-0.15 0.18 -0.075" rpy="-1.57 0 0"/>
    <axis xyz="0 0 1"/>
    <dynamics damping="0.1" friction="0.1"/>
  </joint>

  <!-- Rear Right Wheel (Drive Wheel) -->
  <link name="rear_right_wheel">
    <visual>
      <geometry>
        <cylinder radius="0.08" length="0.05"/>
      </geometry>
      <origin xyz="0 0 0" rpy="0 0 0"/>
      <material name="black">
        <color rgba="0 0 0 1"/>
      </material>
    </visual>

    <collision>
      <geometry>
        <cylinder radius="0.08" length="0.05"/>
      </geometry>
      <origin xyz="0 0 0" rpy="0 0 0"/>
    </collision>

    <inertial>
      <mass value="0.5"/>
      <inertia ixx="0.001" ixy="0" ixz="0" iyy="0.001" iyz="0" izz="0.0016"/>
    </inertial>
  </link>

  <joint name="base_to_rear_right_wheel" type="continuous">
    <parent link="base_link"/>
    <child link="rear_right_wheel"/>
    <origin xyz="-0.15 -0.18 -0.075" rpy="1.57 0 0"/>
    <axis xyz="0 0 -1"/>
    <dynamics damping="0.1" friction="0.1"/>
  </joint>

  <!-- Front Wheel (Single Steered Wheel for Tricycle) -->
  <link name="front_wheel">
    <visual>
      <geometry>
        <cylinder radius="0.08" length="0.05"/>
      </geometry>
      <origin xyz="0 0 0" rpy="0 0 0"/>
      <material name="black">
        <color rgba="0 0 0 1"/>
      </material>
    </visual>

    <collision>
      <geometry>
        <cylinder radius="0.08" length="0.05"/>
      </geometry>
      <origin xyz="0 0 0" rpy="0 0 0"/>
    </collision>

    <inertial>
      <mass value="0.5"/>
      <inertia ixx="0.001" ixy="0" ixz="0" iyy="0.001" iyz="0" izz="0.0016"/>
    </inertial>
  </link>

  <joint name="base_to_front_wheel" type="continuous">
    <parent link="base_link"/>
    <child link="front_wheel"/>
    <origin xyz="0.15 0 -0.075" rpy="-1.57 0 0"/>
    <axis xyz="0 0 1"/>
    <dynamics damping="0.0" friction="0.5"/>
  </joint>

  <!-- Camera Link -->
  <link name="camera_link">
    <visual>
      <geometry>
        <box size="0.05 0.08 0.05"/>
      </geometry>
      <origin xyz="0 0 0" rpy="0 0 0"/>
      <material name="red">
        <color rgba="1 0 0 1"/>
      </material>
    </visual>

    <collision>
      <geometry>
        <box size="0.05 0.08 0.05"/>
      </geometry>
      <origin xyz="0 0 0" rpy="0 0 0"/>
    </collision>

    <inertial>
      <mass value="0.1"/>
      <inertia ixx="0.0001" ixy="0" ixz="0" iyy="0.0001" iyz="0" izz="0.0001"/>
    </inertial>
  </link>

  <joint name="base_to_camera" type="fixed">
    <parent link="base_link"/>
    <child link="camera_link"/>
    <origin xyz="0.25 0 0.1" rpy="0 0 0"/>
  </joint>

  <!-- Gazebo Materials -->
  <gazebo reference="base_link">
    <material>Gazebo/Blue</material>
  </gazebo>

  <gazebo reference="rear_left_wheel">
    <material>Gazebo/Black</material>
    <mu1>1.0</mu1>
    <mu2>1.0</mu2>
  </gazebo>

  <gazebo reference="rear_right_wheel">
    <material>Gazebo/Black</material>
    <mu1>1.0</mu1>
    <mu2>1.0</mu2>
  </gazebo>

  <gazebo reference="front_wheel">
    <material>Gazebo/Black</material>
    <mu1>0.5</mu1>
    <mu2>0.5</mu2>
  </gazebo>

  <gazebo reference="camera_link">
    <material>Gazebo/Red</material>
  </gazebo>

  <!-- Tricycle Drive Plugin -->
  <gazebo>
    <plugin name="tricycle_drive_controller" filename="libgazebo_ros_tricycle_drive.so">
      <update_rate>50</update_rate>
      
      <!-- Steering joint (front wheel) -->
      <steering_joint>base_to_front_wheel</steering_joint>
      
      <!-- Drive joints (rear wheels) -->
      <left_joint>base_to_rear_left_wheel</left_joint>
      <right_joint>base_to_rear_right_wheel</right_joint>
      
      <!-- Wheel properties -->
      <wheel_separation>0.36</wheel_separation>
      <wheel_diameter>0.16</wheel_diameter>
      
      <!-- Wheelbase (distance from rear axle to front wheel) -->
      <wheelbase>0.3</wheelbase>
      
      <!-- Torque and acceleration -->
      <max_wheel_torque>20</max_wheel_torque>
      <max_wheel_acceleration>1.0</max_wheel_acceleration>
      
      <!-- Command and odometry topics -->
      <command_topic>cmd_vel</command_topic>
      <odometry_topic>odom</odometry_topic>
      <odometry_frame>odom</odometry_frame>
      <robot_base_frame>base_link</robot_base_frame>
      
      <!-- Publishing options -->
      <publish_odom>true</publish_odom>
      <publish_odom_tf>true</publish_odom_tf>
      <publish_wheel_tf>false</publish_wheel_tf>
      <publish_wheel_joint_state>true</publish_wheel_joint_state>
    </plugin>
  </gazebo>

  <!-- Camera Sensor Plugin -->
  <gazebo reference="camera_link">
    <sensor type="camera" name="camera1">
      <update_rate>30.0</update_rate>
      <camera name="head">
        <horizontal_fov>1.047</horizontal_fov>
        <image>
          <width>640</width>
          <height>480</height>
          <format>R8G8B8</format>
        </image>
        <clip>
          <near>0.05</near>
          <far>0.5</far>
        </clip>
      </camera>
      <plugin name="camera_controller" filename="libgazebo_ros_camera.so">
        <alwaysOn>true</alwaysOn>
        <updateRate>0.0</updateRate>
        <cameraName>camera</cameraName>
        <imageTopicName>image_raw</imageTopicName>
        <cameraInfoTopicName>camera_info</cameraInfoTopicName>
        <frameName>camera_link</frameName>
      </plugin>
    </sensor>
  </gazebo>

  <!-- LiDAR Link -->
  <link name="lidar_link">
    <visual>
      <geometry>
        <cylinder radius="0.05" length="0.04"/>
      </geometry>
      <origin xyz="0 0 0" rpy="0 0 0"/>
      <material name="red">
        <color rgba="1 0 0 1"/>
      </material>
    </visual>

    <collision>
      <geometry>
        <cylinder radius="0.05" length="0.04"/>
      </geometry>
      <origin xyz="0 0 0" rpy="0 0 0"/>
    </collision>

    <inertial>
      <mass value="0.1"/>
      <inertia ixx="0.0001" ixy="0" ixz="0" iyy="0.0001" iyz="0" izz="0.0001"/>
    </inertial>
  </link>

  <joint name="lidar_joint" type="fixed">
    <parent link="base_link"/>
    <child link="lidar_link"/>
    <origin xyz="0.2 0 0.1" rpy="0 0 0"/>
  </joint>

  <!-- LiDAR Sensor Plugin -->
  <gazebo reference="lidar_link">
    <sensor type="ray" name="lidar">
      <pose>0 0 0 0 0 0</pose>
      <visualize>true</visualize>
      <update_rate>10</update_rate>
      <ray>
        <scan>
          <horizontal>
            <samples>360</samples>
            <resolution>1</resolution>
            <min_angle>-3.14159</min_angle>
            <max_angle>3.14159</max_angle>
          </horizontal>
        </scan>
        <range>
          <min>0.1</min>
          <max>10.0</max>
          <resolution>0.01</resolution>
        </range>
      </ray>
      <plugin name="gazebo_ros_lidar" filename="libgazebo_ros_ray_sensor.so">
        <ros>
          <namespace>/</namespace>
          <remapping>~/out:=scan</remapping>
        </ros>
        <output_type>sensor_msgs/LaserScan</output_type>
        <frame_name>lidar_link</frame_name>
      </plugin>
    </sensor>
  </gazebo>

</robot>
